<?xml version="1.0" encoding="utf-8"?>
<robot xmlns:xacro="http://www.ros.org/wiki/xacro" name="UGV_Unimelb_wheel" >

<xacro:macro name="UGV_Unimelb_wheel" 
        params="wheel_prefix *inertial_pose *visual_pose *collision_pose *joint_pose" >
    <link name="${wheel_prefix}_wheel" >
        <inertial>
            <mass value="1.0" />
            <xacro:insert_block name="inertial_pose" />
            <inertia
                ixx="0.007166667"
                ixy="0"
                ixz="0"
                iyy="0.009"
                iyz="0"
                izz="0.007166667" />
        </inertial>
        <visual> 
            <xacro:insert_block name="visual_pose" />
            <geometry>
                <mesh filename="package://ugv_description/models/Left_Front_Wheel.STL" />
                <surface>
                    <friction>
                        <ode>
                        <kp>10000000</kp>
                        <kd>100</kd>
                        <mu1>1.0</mu1>
                        <mu2>1.0</mu2>
                        </ode>
                    </friction>
                </surface>
            </geometry>
        </visual>
        <collision>
            <xacro:insert_block name="collision_pose" />
            <geometry>
                <cylinder length="0.08" radius="0.06"/>
                <surface>
                    <friction>
                        <ode>
                        <kp>100000000</kp>
                        <kd>1000</kd>
                        <mu1>1.0</mu1>
                        <mu2>1.0</mu2>
                        </ode>
                    </friction>
                </surface>
            </geometry>
            <material>Gazebo/FlatBlack</material>
        </collision>
    </link>

    <joint name="${wheel_prefix}_wheel_joint" type="continuous" >
        <parent link="base_link" />
        <child link="${wheel_prefix}_wheel" />
        <axis xyz="0 1 0" rpy="0 0 0" />
        <xacro:insert_block name="joint_pose" />
        <dynamics damping="0.7" friction="1.0" />
    </joint>

    <transmission name="${wheel_prefix}_wheel_trans" >
        <type>transmission_interface/SimpleTransmission</type>
        <joint name="${wheel_prefix}_wheel_joint" >
            <hardwareInterface>hardware_interface/VelocityJointInterface</hardwareInterface>
        </joint>
        <actuator name="${wheel_prefix}_wheel_motor" >
            <hardwareInterface>VelocityJointInterface</hardwareInterface>
            <mechanicalReduction>7</mechanicalReduction>
        </actuator>
    </transmission>

</xacro:macro>
</robot>
